Traceback (most recent call last):
  File "/media/aadvik/Media/Workspaces/Python/05_Exceptions/5.1_RaiseAndAssertStmts.py", line 25, in <module>
    raise Exception('This is the error message.')
Exception: This is the error message.
Traceback (most recent call last):
  File "/media/aadvik/Media/Workspaces/Python/05_Exceptions/5.1_RaiseAndAssertStmts.py", line 25, in <module>
    raise Exception('This is the error message.')
Exception: This is the error message.
